<?xml version="1.0"?>
<robot name="placebot" xmlns:xacro="http://www.ros.org/wiki/xacro">

  <xacro:property name="laser_size_x" value="0.02"/>
  <xacro:property name="laser_size_y" value="0.02"/>
  <xacro:property name="laser_size_z" value="0.04"/>
  <xacro:property name="laser_origin_x" value="0.5"/>
  <xacro:property name="laser_origin_y" value="0.35"/>
  <xacro:property name="laser_origin_z" value="0.09"/>
  <xacro:property name="PI" value="3.14159265358979323846"/>
  
  <xacro:macro name="default_inertial" params="mass">
    <inertial>
      <mass value="${mass}"/>
      <inertia ixx="1.0" ixy="0.0" ixz="0.0" iyy="1.0" iyz="0.0" izz="1.0"/>
    </inertial>
  </xacro:macro>
  
  <gazebo reference="base_footprint">
    <turnGravityOff>false</turnGravityOff>
  </gazebo>
  
  <gazebo reference="base_link">
    <material>Gazebo/SkyBlue</material>
  </gazebo>
    
  <gazebo reference="right_front_steering_link">
    <material>Gazebo/Green</material>
    <mu1>1.0</mu1>
    <mu2>1.0</mu2>
  </gazebo>
    
  <gazebo reference="left_front_steering_link">
    <material>Gazebo/Green</material>
    <mu1>1.0</mu1>
    <mu2>1.0</mu2>
  </gazebo>
  
  <gazebo reference="right_rear_steering_link">
    <material>Gazebo/Green</material>
    <mu1>1.0</mu1>
    <mu2>1.0</mu2>
  </gazebo>
  
  <gazebo reference="left_rear_steering_link">
    <material>Gazebo/Green</material>
    <mu1>1.0</mu1>
    <mu2>1.0</mu2>
  </gazebo>
    
  <gazebo reference="right_front_axle_link">
    <material>Gazebo/Black</material>
  </gazebo>
    
  <gazebo reference="left_front_axle_link">
    <material>Gazebo/Black</material>
  </gazebo>
  
  <gazebo reference="right_rear_axle_link">
    <material>Gazebo/Black</material>
  </gazebo>
  
  <gazebo reference="left_rear_axle_link">
    <material>Gazebo/Black</material>
  </gazebo>
  
  <gazebo reference="right_front_wheel">
    <material>Gazebo/Gray</material>
    <!--<mu1>1.0</mu1>
	<mu2>1.0</mu2>
	<kp>1000000.0</kp>
	<kd>100.0</kd>-->
	<collision>
        <surface>
          <friction>
            <ode>
              <mu>100000.0</mu>
              <mu2>100000.0</mu2>
              <slip1>0.0</slip1>
              <slip2>0.0</slip2>
            </ode>
          </friction>
        </surface>
	</collision>
  </gazebo>
  
  <gazebo reference="left_front_wheel">
    <material>Gazebo/Gray</material>
    <!--<mu1>1.0</mu1>
	<mu2>1.0</mu2>
	<kp>1000000.0</kp>
	<kd>100.0</kd>-->
	<collision>
        <surface>
          <friction>
            <ode>
              <mu>100000.0</mu>
              <mu2>100000.0</mu2>
              <slip1>0.0</slip1>
              <slip2>0.0</slip2>
            </ode>
          </friction>
        </surface>
	</collision>
  </gazebo>
  
  <gazebo reference="right_rear_wheel">
    <material>Gazebo/Gray</material>
    <!--<mu1>1.0</mu1>
	<mu2>1.0</mu2>
	<kp>1000000.0</kp>
	<kd>100.0</kd>-->
	<collision>
        <surface>
          <friction>
            <ode>
              <mu>100000.0</mu>
              <mu2>100000.0</mu2>
              <slip1>0.0</slip1>
              <slip2>0.0</slip2>
            </ode>
          </friction>
        </surface>
	</collision>
  </gazebo>
  
  <gazebo reference="left_rear_wheel">
    <material>Gazebo/Gray</material>
    <!--<mu1>1.0</mu1>
	<mu2>1.0</mu2>
	<kp>1000000.0</kp>
	<kd>100.0</kd>-->
	<collision>
        <surface>
          <friction>
            <ode>
              <mu>100000.0</mu>
              <mu2>100000.0</mu2>
              <slip1>0.0</slip1>
              <slip2>0.0</slip2>
            </ode>
          </friction>
        </surface>
	</collision>
  </gazebo>
  
  <material name="red">
    <color rgba="0.8 0 0 1"/>
  </material>

  <material name="green">
    <color rgba="0 0.8 0 1"/>
  </material>

  <material name="blue">
    <color rgba="0 0 0.8 1"/>
  </material>

  <material name="none">
    <color rgba="0 0 0 0"/>
  </material>
  
  <link name="base_footprint">
    <visual>
      <geometry>
        <box size="0.001 0.001 0.001"/>
      </geometry>
      <origin xyz="0 0 0"/>
    </visual>
        
    <!-- <inertial>
      <origin xyz="0 0 0" rpy="0 0 0"/>
      <mass value="0.0001"/>
      <inertia
        ixx="0.0001" ixy="0.0" ixz="0.0"
        iyy="0.0001" iyz="0.0"
        izz="0.0001"/>
    </inertial> -->
  </link>

  <link name="base_link">
    <collision>
      <geometry>
        <box size="0.9 0.6 0.02"/>
      </geometry>
      <origin xyz="0 0 0"/>
    </collision>
    
    <visual>
      <geometry>
        <box size="0.9 0.6 0.02"/>
      </geometry>
      <origin xyz="0 0 0"/>
      <material name="blue"/>
    </visual>
        
    <inertial>
      <origin xyz="0 0 0" rpy="0 0 0"/>
      <mass value="50"/>
      <inertia
        ixx="${50 * (0.6 * 0.6 + 0.02 * 0.02) / 12}" ixy="0.0" ixz="0.0"
        iyy="${50 * (0.9 * 0.9 + 0.02 * 0.02) / 12}" iyz="0.0"
        izz="${50 * (0.6 * 0.6 + 0.9 * 0.9) / 12}"/>
    </inertial>
  </link>

  <joint name="ground_to_base" type="fixed">
    <parent link="base_footprint"/>
    <child link="base_link"/>
    <origin xyz="0 0 0.21" rpy="0 0 0"/>
  </joint>

  <link name="right_front_steering_link">
    <collision>
      <geometry>
        <cylinder length="0.13" radius="0.01"/>
      </geometry>
      <origin rpy="0 0 0" xyz="0 0 0"/>
    </collision>
    
    <visual>
      <geometry>
        <cylinder length="0.13" radius="0.01"/>
      </geometry>
      <origin rpy="0 0 0" xyz="0 0 0"/>
      <material name="green"/>
    </visual>
    
    <inertial>
      <origin xyz="0 0 0" rpy="0 0 0"/>
      <mass value="0.001"/>
      <inertia
        ixx="0.001" ixy="0.0" ixz="0.0"
        iyy="0.001" iyz="0.0"
        izz="0.001"/>
    </inertial>
  </link>

  <joint name="base_to_RFSL" type="fixed">
    <parent link="base_link"/>
    <child link="right_front_steering_link"/>
    <origin xyz="0.35 -0.22 -0.055"/>
  </joint>
  
  <link name="right_front_axle_link">
    <!-- <collision>
      <geometry>
        <cylinder length="0.1" radius="0.01"/>
      </geometry>
      <origin rpy="0 0 0" xyz="0 0 0.06"/>
    </collision>
    
    <visual>
      <geometry>
        <cylinder length="0.1" radius="0.01"/>
      </geometry>
      <origin rpy="0 0 0" xyz="0 0 0.06"/>
      <material name="green"/>
    </visual> -->
    
    <inertial>
      <origin xyz="0 0 0" rpy="0 0 0"/>
      <mass value="0.001"/>
      <inertia
        ixx="0.001" ixy="0.0" ixz="0.0"
        iyy="0.001" iyz="0.0"
        izz="0.001"/>
    </inertial>
  </link>
  
  <joint name="right_front_steering_joint" type="revolute">
    <parent link="right_front_steering_link"/>
    <child link="right_front_axle_link"/>
    <origin xyz="0 0 -0.065" rpy="0 0 0"/>
    <axis xyz="0 0 1" rpy="0 0 0"/>
    <!-- lower and upper angle limits (90deg = 1.57rad)
      velocity limit = 60deg/sec = 1.0472rad/sec
      effort limit = 34 * 19 / 30 = 21.5 Nm (traction wheel rated at 34 Nm)
      traction gear ratio = 30; orientation gear ratio = 19 -->
    <limit lower="-1.57" upper="1.57" velocity="1.0472" effort="300"/>
    <!-- <dynamics friction="0"/> -->
  </joint>
  
  <transmission name="right_front_steering_trans">
	<type>transmission_interface/SimpleTransmission</type>
	<joint name="right_front_steering_joint">
      <hardwareInterface>hardware_interface/EffortJointInterface</hardwareInterface>
	</joint>
	<actuator name="right_front_steering_act">
	  <!-- This hardwareInterface element exists for compatibility
			 with ROS Hydro. -->
	  <hardwareInterface>hardware_interface/EffortJointInterface</hardwareInterface>
	  <mechanicalReduction>1</mechanicalReduction>
	</actuator>
  </transmission>
      
  <link name="right_front_wheel">
  	<collision>
      <geometry>
        <cylinder length="0.03" radius="0.09"/>
      </geometry>
      <origin rpy="0 0 0" xyz="0 0 0"/>
    </collision>
    
    <visual>
      <geometry>
        <cylinder length="0.03" radius="0.09"/>
      </geometry>
      <origin rpy="0 0 0" xyz="0 0 0"/>
      <material name="red"/>
    </visual>
    
    <inertial>
      <origin xyz="0 0 0" rpy="0 0 0"/>
      <mass value="1"/>
      <inertia
        ixx="${1 * (3 * 0.09 * 0.09 + 0.03 * 0.03) / 12}" ixy="0.0" ixz="0.0"
        iyy="${1 * (3 * 0.09 * 0.09 + 0.03 * 0.03) / 12}" iyz="0.0"
        izz="${1 * 0.09 * 0.09 / 2}"/>
    </inertial>
  </link>

  <joint name="right_front_axle" type="continuous">
    <parent link="right_front_axle_link"/>
    <child link="right_front_wheel"/>
    <origin xyz="0 0.0 0" rpy="${PI/2} 0 0"/>
    <axis rpy="0 0 0" xyz="0 0 -1"/>
    <!-- velocity limit = 100 rpm = 10.5 rad/sec
      effort limit = 34 Nm (traction wheel rated at 34 Nm) -->
    <limit velocity="10.5" effort="500"/>
    <dynamics friction="10" damping="1.0"/>
  </joint>
  
  <transmission name="right_front_axle_trans">
	<type>transmission_interface/SimpleTransmission</type>
	<joint name="right_front_axle">
      <hardwareInterface>hardware_interface/EffortJointInterface</hardwareInterface>
	</joint>
	<actuator name="right_front_axle_act">
	  <!-- This hardwareInterface element exists for compatibility
			 with ROS Hydro. -->
	  <hardwareInterface>hardware_interface/EffortJointInterface</hardwareInterface>
	  <mechanicalReduction>1</mechanicalReduction>
	</actuator>
  </transmission>
  
  <link name="left_front_steering_link">
    <collision>
      <geometry>
        <cylinder length="0.13" radius="0.01"/>
      </geometry>
      <origin rpy="0 0 0" xyz="0 0 0"/>
    </collision>
    
    <visual>
      <geometry>
        <cylinder length="0.13" radius="0.01"/>
      </geometry>
      <origin rpy="0 0 0" xyz="0 0 0"/>
      <material name="green"/>
    </visual>
    
    <!-- <inertial>
      <origin xyz="0 0 0" rpy="0 0 0"/>
      <mass value="8.5"/>
      <inertia
        ixx="0.00122" ixy="0.0" ixz="0.0"
        iyy="0.00122" iyz="0.0"
        izz="0.000425"/>
    </inertial> -->
    <inertial>
      <origin xyz="0 0 0" rpy="0 0 0"/>
      <mass value="0.001"/>
      <inertia
        ixx="0.001" ixy="0.0" ixz="0.0"
        iyy="0.001" iyz="0.0"
        izz="0.001"/>
    </inertial>
  </link>

  <joint name="base_to_LFSL" type="fixed">
    <parent link="base_link"/>
    <child link="left_front_steering_link"/>
    <origin xyz="0.35 0.22 -0.055"/>
  </joint>
  
  <link name="left_front_axle_link">
    <inertial>
      <origin xyz="0 0 0" rpy="0 0 0"/>
      <mass value="0.001"/>
      <inertia
        ixx="0.001" ixy="0.0" ixz="0.0"
        iyy="0.001" iyz="0.0"
        izz="0.001"/>
    </inertial>
  </link>
  
  <joint name="left_front_steering_joint" type="revolute">
    <parent link="left_front_steering_link"/>
    <child link="left_front_axle_link"/>
    <origin xyz="0 0 -0.065"/>
    <axis rpy="0 0 0" xyz="0 0 1"/>
    <!-- lower and upper angle limits (90deg = 1.57rad)
      velocity limit = 60deg/sec = 1.0472rad/sec
      effort limit = 34 * 19 / 30 = 21.5 Nm (traction wheel rated at 34 Nm)
      traction gear ratio = 30; orientation gear ratio = 19 -->
    <limit lower="-1.57" upper="1.57" velocity="1.0472" effort="300"/>
    <!-- <dynamics friction="0"/> -->
  </joint>
  
  <transmission name="left_front_steering_trans">
	<type>transmission_interface/SimpleTransmission</type>
	<joint name="left_front_steering_joint">
      <hardwareInterface>hardware_interface/EffortJointInterface</hardwareInterface>
	</joint>
	<actuator name="left_front_steering_act">
	  <!-- This hardwareInterface element exists for compatibility
			 with ROS Hydro. -->
	  <hardwareInterface>hardware_interface/EffortJointInterface</hardwareInterface>
	  <mechanicalReduction>1</mechanicalReduction>
	</actuator>
  </transmission>
      
  <link name="left_front_wheel">
  	<collision>
      <geometry>
        <cylinder length="0.03" radius="0.09"/>
      </geometry>
      <origin rpy="0 0 0" xyz="0 0 0"/>
    </collision>
    
    <visual>
      <geometry>
        <cylinder length="0.03" radius="0.09"/>
      </geometry>
      <origin rpy="0 0 0" xyz="0 0 0"/>
      <material name="red"/>
    </visual>
    
    <inertial>
      <origin xyz="0 0 0" rpy="0 0 0"/>
      <mass value="1"/>
      <inertia
        ixx="${1 * (3 * 0.09 * 0.09 + 0.03 * 0.03) / 12}" ixy="0.0" ixz="0.0"
        iyy="${1 * (3 * 0.09 * 0.09 + 0.03 * 0.03) / 12}" iyz="0.0"
        izz="${1 * 0.09 * 0.09 / 2}"/>
    </inertial>
  </link>

  <joint name="left_front_axle" type="continuous">
    <parent link="left_front_axle_link"/>
    <child link="left_front_wheel"/>
    <origin xyz="0 0.0 0" rpy="${-PI/2} 0 0"/>
    <axis rpy="0 0 0" xyz="0 0 1"/>
    <!-- velocity limit = 100 rpm = 10.5 rad/sec
      effort limit = 34 Nm (traction wheel rated at 34 Nm) -->
    <limit velocity="10.5" effort="500"/>
    <dynamics friction="10" damping="1.0"/>
  </joint>
  
  <transmission name="left_front_axle_trans">
	<type>transmission_interface/SimpleTransmission</type>
	<joint name="left_front_axle">
      <hardwareInterface>hardware_interface/EffortJointInterface</hardwareInterface>
	</joint>
	<actuator name="left_front_axle_act">
	  <!-- This hardwareInterface element exists for compatibility
			 with ROS Hydro. -->
	  <hardwareInterface>hardware_interface/EffortJointInterface</hardwareInterface>
	  <mechanicalReduction>1</mechanicalReduction>
	</actuator>
  </transmission>
  
  <link name="right_rear_steering_link">
    <collision>
      <geometry>
        <cylinder length="0.13" radius="0.01"/>
      </geometry>
      <origin rpy="0 0 0" xyz="0 0 0"/>
    </collision>
    
    <visual>
      <geometry>
        <cylinder length="0.13" radius="0.01"/>
      </geometry>
      <origin rpy="0 0 0" xyz="0 0 0"/>
      <material name="green"/>
    </visual>
    
    <inertial>
      <origin xyz="0 0 0" rpy="0 0 0"/>
      <mass value="0.001"/>
      <inertia
        ixx="0.001" ixy="0.0" ixz="0.0"
        iyy="0.001" iyz="0.0"
        izz="0.001"/>
    </inertial>
  </link>

  <joint name="base_to_RRSL" type="fixed">
    <parent link="base_link"/>
    <child link="right_rear_steering_link"/>
    <origin xyz="-0.35 -0.22 -0.055"/>
  </joint>
  
  <link name="right_rear_axle_link">
    <inertial>
      <origin xyz="0 0 0" rpy="0 0 0"/>
      <mass value="0.001"/>
      <inertia
        ixx="0.001" ixy="0.0" ixz="0.0"
        iyy="0.001" iyz="0.0"
        izz="0.001"/>
    </inertial>
  </link>
  
  <joint name="right_rear_steering_joint" type="revolute">
    <parent link="right_rear_steering_link"/>
    <child link="right_rear_axle_link"/>
    <origin xyz="0 0 -0.065"/>
    <axis xyz="0 0 1" rpy="0 0 0"/>
    <!-- lower and upper angle limits (90deg = 1.57rad)
      velocity limit = 60deg/sec = 1.0472rad/sec
      effort limit = 34 * 19 / 30 = 21.5 Nm (traction wheel rated at 34 Nm)
      traction gear ratio = 30; orientation gear ratio = 19 -->
    <limit lower="-1.57" upper="1.57" velocity="1.0472" effort="300"/>
  </joint>
  
  <transmission name="right_rear_steering_trans">
	<type>transmission_interface/SimpleTransmission</type>
	<joint name="right_rear_steering_joint">
      <hardwareInterface>hardware_interface/EffortJointInterface</hardwareInterface>
	</joint>
	<actuator name="right_rear_steering_act">
	  <hardwareInterface>hardware_interface/EffortJointInterface</hardwareInterface>
	  <mechanicalReduction>1</mechanicalReduction>
	</actuator>
  </transmission>
      
  <link name="right_rear_wheel">
  	<collision>
      <geometry>
        <cylinder length="0.03" radius="0.09"/>
      </geometry>
      <origin rpy="0 0 0" xyz="0 0 0"/>
    </collision>
    
    <visual>
      <geometry>
        <cylinder length="0.03" radius="0.09"/>
      </geometry>
      <origin rpy="0 0 0" xyz="0 0 0"/>
      <material name="red"/>
    </visual>
    
    <inertial>
      <origin xyz="0 0 0" rpy="0 0 0"/>
      <mass value="1"/>
      <inertia
        ixx="${1 * (3 * 0.09 * 0.09 + 0.03 * 0.03) / 12}" ixy="0.0" ixz="0.0"
        iyy="${1 * (3 * 0.09 * 0.09 + 0.03 * 0.03) / 12}" iyz="0.0"
        izz="${1 * 0.09 * 0.09 / 2}"/>
    </inertial>
  </link>

  <joint name="right_rear_axle" type="continuous">
    <parent link="right_rear_axle_link"/>
    <child link="right_rear_wheel"/>
    <origin xyz="0 0.0 0" rpy="${PI/2} 0 0"/>
    <axis rpy="0 0 0" xyz="0 0 -1"/>
    <!-- velocity limit = 100 rpm = 10.5 rad/sec
      effort limit = 34 Nm (traction wheel rated at 34 Nm) -->
    <limit velocity="10.5" effort="500"/>
    <dynamics friction="10" damping="1.0"/>
  </joint>
  
  <transmission name="right_rear_axle_trans">
	<type>transmission_interface/SimpleTransmission</type>
	<joint name="right_rear_axle">
      <hardwareInterface>hardware_interface/EffortJointInterface</hardwareInterface>
	</joint>
	<actuator name="right_rear_axle_act">
	  <!-- This hardwareInterface element exists for compatibility
			 with ROS Hydro. -->
	  <hardwareInterface>hardware_interface/EffortJointInterface</hardwareInterface>
	  <mechanicalReduction>1</mechanicalReduction>
	</actuator>
  </transmission>
  
  <link name="left_rear_steering_link">
    <collision>
      <geometry>
        <cylinder length="0.13" radius="0.01"/>
      </geometry>
      <origin rpy="0 0 0" xyz="0 0 0"/>
    </collision>
    
    <visual>
      <geometry>
        <cylinder length="0.13" radius="0.01"/>
      </geometry>
      <origin rpy="0 0 0" xyz="0 0 0"/>
      <material name="green"/>
    </visual>
    
    <inertial>
      <origin xyz="0 0 0" rpy="0 0 0"/>
      <mass value="0.001"/>
      <inertia
        ixx="0.001" ixy="0.0" ixz="0.0"
        iyy="0.001" iyz="0.0"
        izz="0.001"/>
    </inertial>
  </link>

  <joint name="base_to_LRSL" type="fixed">
    <parent link="base_link"/>
    <child link="left_rear_steering_link"/>
    <origin xyz="-0.35 0.22 -0.055"/>
  </joint>
  
  <link name="left_rear_axle_link">
    <inertial>
      <origin xyz="0 0 0" rpy="0 0 0"/>
      <mass value="0.001"/>
      <inertia
        ixx="0.001" ixy="0.0" ixz="0.0"
        iyy="0.001" iyz="0.0"
        izz="0.001"/>
    </inertial>
  </link>
  
  <joint name="left_rear_steering_joint" type="revolute">
    <parent link="left_rear_steering_link"/>
    <child link="left_rear_axle_link"/>
    <origin xyz="0 0 -0.065"/>
    <axis xyz="0 0 1" rpy="0 0 0"/>
    <!-- lower and upper angle limits (90deg = 1.57rad)
      velocity limit = 60deg/sec = 1.0472rad/sec
      effort limit = 34 * 19 / 30 = 21.5 Nm (traction wheel rated at 34 Nm)
      traction gear ratio = 30; orientation gear ratio = 19 -->
    <limit lower="-1.57" upper="1.57" velocity="1.0472" effort="300"/>
    <!-- <dynamics friction="0"/> -->
  </joint>
  
  <transmission name="left_rear_steering_trans">
	<type>transmission_interface/SimpleTransmission</type>
	<joint name="left_rear_steering_joint">
      <hardwareInterface>hardware_interface/EffortJointInterface</hardwareInterface>
	</joint>
	<actuator name="left_rear_steering_act">
	  <hardwareInterface>hardware_interface/EffortJointInterface</hardwareInterface>
	  <mechanicalReduction>1</mechanicalReduction>
	</actuator>
  </transmission>
      
  <link name="left_rear_wheel">
  	<collision>
      <geometry>
        <cylinder length="0.03" radius="0.09"/>
      </geometry>
      <origin rpy="0 0 0" xyz="0 0 0"/>
    </collision>
    
    <visual>
      <geometry>
        <cylinder length="0.03" radius="0.09"/>
      </geometry>
      <origin rpy="0 0 0" xyz="0 0 0"/>
      <material name="red"/>
    </visual>
    
    <inertial>
      <origin xyz="0 0 0" rpy="0 0 0"/>
      <mass value="1"/>
      <inertia
        ixx="${1 * (3 * 0.09 * 0.09 + 0.03 * 0.03) / 12}" ixy="0.0" ixz="0.0"
        iyy="${1 * (3 * 0.09 * 0.09 + 0.03 * 0.03) / 12}" iyz="0.0"
        izz="${1 * 0.09 * 0.09 / 2}"/>
    </inertial>
  </link>

  <joint name="left_rear_axle" type="continuous">
    <parent link="left_rear_axle_link"/>
    <child link="left_rear_wheel"/>
    <origin xyz="0 0 0" rpy="${-PI/2} 0 0"/>
    <axis rpy="0 0 0" xyz="0 0 1"/>
    <!-- velocity limit = 100 rpm = 10.5 rad/sec
      effort limit = 34 Nm (traction wheel rated at 34 Nm) -->
    <limit velocity="10.5" effort="500"/>
    <dynamics friction="10" damping="1.0"/>
  </joint>
  
  <transmission name="left_rear_axle_trans">
	<type>transmission_interface/SimpleTransmission</type>
	<joint name="left_rear_axle">
      <hardwareInterface>hardware_interface/EffortJointInterface</hardwareInterface>
	</joint>
	<actuator name="left_rear_axle_act">
	  <!-- This hardwareInterface element exists for compatibility
			 with ROS Hydro. -->
	  <hardwareInterface>hardware_interface/EffortJointInterface</hardwareInterface>
	  <mechanicalReduction>1</mechanicalReduction>
	</actuator>
  </transmission>
  
  <!--Laser Scan-->
  <link name="front_sensor_laser">
    <visual>
      <geometry>
        <mesh filename="package://placebot_description/meshes/sick_s300.dae"/>
        <!--box size="${laser_size_x} ${laser_size_y} ${laser_size_z}"/-->
      </geometry>
      <material name="blue"/>
    </visual>
    <collision>
      <geometry>
        <mesh filename="package://placebot_description/meshes/sick_s300.dae"/>
      </geometry>
    </collision>
    <inertial>
	  <mass value="1e-5" />
	  <origin xyz="0 0 0" rpy="0 0 0"/>
	  <inertia ixx="1e-6" ixy="0" ixz="0" iyy="1e-6" iyz="0" izz="1e-6" />
	</inertial>
  </link>

  <joint name="front_sensor_laser_joint" type="fixed">
    <origin xyz="${laser_origin_x} ${laser_origin_y} ${laser_origin_z}" rpy="0 0 ${3.14159265358979323846/4}" />
    <parent link="base_link"/>
    <child link="front_sensor_laser" />
  </joint>

  <!--Laser Scan-->
  <link name="rear_sensor_laser">
    <visual>
      <geometry>
        <mesh filename="package://placebot_description/meshes/sick_s300.dae"/>
        <!--box size="${laser_size_x} ${laser_size_y} ${laser_size_z}"/-->
      </geometry>
      <material name="blue"/>
    </visual>
    <collision>
      <geometry>
        <mesh filename="package://placebot_description/meshes/sick_s300.dae"/>
      </geometry>
    </collision>
    <inertial>
	  <mass value="1e-5" />
	  <origin xyz="0 0 0" rpy="0 0 0"/>
	  <inertia ixx="1e-6" ixy="0" ixz="0" iyy="1e-6" iyz="0" izz="1e-6" />
	</inertial>
  </link>

  <joint name="rear_sensor_laser_joint" type="fixed">
    <origin xyz="${-laser_origin_x} ${-laser_origin_y} ${laser_origin_z}" rpy="0 0 ${-3*3.14159265358979323846/4}" />
    <parent link="base_link"/>
    <child link="rear_sensor_laser" />
  </joint>
   
  <!-- <gazebo>
    <plugin filename="libgazebo_ros_diff_drive.so" name="differential_drive_controller_front">
      <rosDebugLevel>Debug</rosDebugLevel>
      <publishWheelTF>True</publishWheelTF>
      <publishTf>1</publishTf>
      <publishWheelJointState>true</publishWheelJointState>
      <alwaysOn>true</alwaysOn>
      <updateRate>50.0</updateRate>
      <legacyMode>false</legacyMode>
      <leftJoint>LRW_to_LRWL</leftJoint>
      <rightJoint>RRW_to_RRWL</rightJoint>
      <wheelSeparation>0.51</wheelSeparation>
      <wheelDiameter>0.09</wheelDiameter>
      <broadcastTF>1</broadcastTF>
      <wheelTorque>30</wheelTorque>
      <wheelAcceleration>1.8</wheelAcceleration>
      <commandTopic>cmd_vel</commandTopic>
      <odometryFrame>odom</odometryFrame>
      <odometryTopic>odom</odometryTopic>
      <robotBaseFrame>base_link</robotBaseFrame>
    </plugin>
  </gazebo> -->
  
  <gazebo>
    <plugin name="gazebo_ros_control" filename="libgazebo_ros_control.so">
      <legacyModeNS>false</legacyModeNS>
    </plugin>
  </gazebo>
  
  <!--Gazebo sick_s300 Laser Plugin-->
  <gazebo reference="front_sensor_laser">
    <mu1>1.0</mu1>
    <mu2>1.0</mu2>
	<!-- use type="ray" if is no graphics card -->
    <sensor type="gpu_ray" name="front_sicks300_sensor">
      <pose>0 0 0 0 0 0</pose>
      <visualize>false</visualize>
      <update_rate>10</update_rate>
      <ray>
        <scan>
          <horizontal>
            <samples>541</samples>
            <resolution>1</resolution>
            <min_angle>${-3*PI/4}</min_angle>
            <max_angle>${3*PI/4}</max_angle>
          </horizontal>
        </scan>
        <range>
          <min>0.1</min>
          <max>10</max> <!-- 29.5 -->
          <resolution>0.03</resolution>
        </range>
        <noise>
          <type>gaussian</type>
          <mean>0.0</mean>
          <stddev>0.01</stddev>
        </noise>
      </ray>
	  <!-- use filename="libgazebo_ros_laser.so" if is no graphics card -->
      <plugin name="front_sicks300_controller" filename="libgazebo_ros_gpu_laser.so">
        <topicName>front_laser/scan</topicName>
        <frameName>front_sensor_laser</frameName>
      </plugin>
    </sensor>
  </gazebo>
  
  <!--Gazebo sick_s300 Laser Plugin-->
  <gazebo reference="rear_sensor_laser">
    <mu1>1.0</mu1>
    <mu2>1.0</mu2>
	<!-- use type="ray" if is no graphics card -->
    <sensor type="gpu_ray" name="rear_sicks300_sensor">
      <pose>0 0 0 0 0 0</pose>
      <visualize>false</visualize>
      <update_rate>10</update_rate>
      <ray>
        <scan>
          <horizontal>
            <samples>541</samples>
            <resolution>1</resolution>
            <min_angle>${-3*PI/4}</min_angle>
            <max_angle>${3*PI/4}</max_angle>
          </horizontal>
        </scan>
        <range>
          <min>0.1</min> <!-- 0.05 -->
          <max>10</max>
          <resolution>0.03</resolution>
        </range>
        <noise>
          <type>gaussian</type>
          <mean>0.0</mean>
          <stddev>0.01</stddev>
        </noise>
      </ray>
	  <!-- use filename="libgazebo_ros_laser.so" if is no graphics card -->
      <plugin name="rear_sicks300_controller" filename="libgazebo_ros_gpu_laser.so">
        <topicName>rear_laser/scan</topicName>
        <frameName>rear_sensor_laser</frameName>
      </plugin>
    </sensor>
  </gazebo>

    <link name="front_border_box">
    <collision>
      <geometry>
        <box size="0.9 0.01 0.2"/>
      </geometry>
      <origin rpy="0 0 0" xyz="0 0 0"/>
    </collision>
    
    <visual>
      <geometry>
        <box size="0.9 0.01 0.2"/>
      </geometry>
      <origin rpy="0 0 0" xyz="0 0 0"/>
      <material name="red"/>
    </visual>
  </link>

  <joint name="front_border_box_joint" type="fixed">
    <origin xyz="0 -0.3 0.1" rpy="0 0 0" />
    <parent link="base_link"/>
    <child link="front_border_box" />
  </joint>

  <gazebo reference="front_border_box">
    <material>Gazebo/SkyBlue</material>
  </gazebo>

    <link name="front_border_box_second">
    <collision>
      <geometry>
        <box size="0.9 0.01 0.2"/>
      </geometry>
      <origin rpy="0 0 0" xyz="0 0 0"/>
    </collision>
    
    <visual>
      <geometry>
        <box size="0.9 0.01 0.2"/>
      </geometry>
      <origin rpy="0 0 0" xyz="0 0 0"/>
      <material name="red"/>
    </visual>
  </link>

  <joint name="front_border_box_second_joint" type="fixed">
    <origin xyz="0 0.3 0.1" rpy="0 0 0" />
    <parent link="base_link"/>
    <child link="front_border_box_second" />
  </joint>

  <gazebo reference="front_border_box_second">
    <material>Gazebo/SkyBlue</material>
  </gazebo>

<link name="front_border_box_third">
    <collision>
      <geometry>
        <box size="0.01 0.6 0.2"/>
      </geometry>
      <origin rpy="0 0 0" xyz="0 0 0"/>
    </collision>
    
    <visual>
      <geometry>
        <box size="0.01 0.6 0.2"/>
      </geometry>
      <origin rpy="0 0 0" xyz="0 0 0"/>
      <material name="red"/>
    </visual>
  </link>

  <joint name="front_border_box_third_joint" type="fixed">
    <origin xyz="0.45 0 0.1" rpy="0 0 0" />
    <parent link="base_link"/>
    <child link="front_border_box_third" />
  </joint>

  <gazebo reference="front_border_box_third">
    <material>Gazebo/SkyBlue</material>
  </gazebo>


<link name="front_border_box_fourth">
    <collision>
      <geometry>
        <box size="0.01 0.6 0.2"/>
      </geometry>
      <origin rpy="0 0 0" xyz="0 0 0"/>
    </collision>
    
    <visual>
      <geometry>
        <box size="0.01 0.6 0.2"/>
      </geometry>
      <origin rpy="0 0 0" xyz="0 0 0"/>
      <material name="red"/>
    </visual>
  </link>

  <joint name="front_border_box_fourth_joint" type="fixed">
    <origin xyz="-0.45 0 0.1" rpy="0 0 0" />
    <parent link="base_link"/>
    <child link="front_border_box_fourth" />
  </joint>

  <gazebo reference="front_border_box_fourth">
    <material>Gazebo/SkyBlue</material>
  </gazebo>











</robot>
